<?xml version="1.0"?>
<robot xmlns:xacro="http://www.ros.org/wiki/xacro">
<xacro:include filename="$(find robot_description)/urdf/bot/common_inertia.xacro" />
    <xacro:macro name="wheel_xacro" params="whell_name xyz">
        <!-- 机器人的IMU 惯性测量 -->
        <link name="${whell_name}_link">
            <!-- 部件外观描述 -->
            <visual>
                <!-- 沿自身几何中心偏移和旋转 -->
                <origin xyz="0.0 0.0 0.0" rpy="1.57079 0.0 0.0"/>
                <!-- 几何形状 -->
                <geometry>
                    <cylinder radius="0.032" length="0.04"/>
                </geometry>
                <!-- 材质和颜色描述 -->
                <material name="yellow">
                    <color rgba="1.0 1.0 0.0 0.8"/>
                </material>
            </visual>
            <collision>
                <!-- 沿自身几何中心偏移和旋转 -->
                <origin xyz="0.0 0.0 0.0" rpy="1.57079 0.0 0.0"/>
                <!-- 几何形状 -->
                <geometry>
                    <cylinder radius="0.032" length="0.04"/>
                </geometry>
                <!-- 材质和颜色描述 -->
                <material name="yellow">
                    <color rgba="1.0 1.0 0.0 0.8"/>
                </material>
            </collision>
            <xacro:cylinder_inertia m="0.05" r="0.032" h="0.04"/>
        </link>
        <!-- 机器人的关节，用于组合机器人的部件 -->
        <joint name="${whell_name}_joint" type="continuous">
            <parent link="base_link"/>
            <child link="${whell_name}_link"/>
            <origin xyz="${xyz}" rpy="0.0 0.0 0.0"/>
            <axis xyz="0 1 0"/>
        </joint>

        <gazebo reference="${whell_name}_link">
            <mu1 value="20.0"/>
            <mu2 value="20.0"/>
            <kp value="1000000000.0"/>
            <kd value="1.0"/>
        </gazebo>
    </xacro:macro>

</robot>
